<?xml version="1.0" ?>
<robot name="robot_rover1" xmlns:xacro="http://www.ros.org/wiki/xacro">

<xacro:include filename="$(find robot_rover1_description)/urdf/materials.xacro" />
<xacro:include filename="$(find robot_rover1_description)/urdf/robot_rover1.trans" />
<xacro:include filename="$(find robot_rover1_description)/urdf/robot_rover1.gazebo" />
<link name="base_link">
  <inertial>
    <origin xyz="-0.0140174084713008 0.0011794096586173642 0.34910515531653014" rpy="0 0 0"/>
    <mass value="30.983889495648246"/>
    <inertia ixx="1.908794" iyy="1.922421" izz="1.85897" ixy="-0.001547" iyz="-0.010801" ixz="-0.010734"/>
  </inertial>
  <visual>
    <origin xyz="0 0 0" rpy="0 0 0"/>
    <geometry>
      <mesh filename="package://robot_rover1_description/meshes/base_link.stl" scale="0.001 0.001 0.001"/>
    </geometry>
    <material name="silver"/>
  </visual>
  <collision>
    <origin xyz="0 0 0" rpy="0 0 0"/>
    <geometry>
      <mesh filename="package://robot_rover1_description/meshes/base_link.stl" scale="0.001 0.001 0.001"/>
    </geometry>
  </collision>
</link>

<link name="right_1">
  <inertial>
    <origin xyz="2.7755575615628914e-16 -0.013999999999998958 -2.498001805406602e-16" rpy="0 0 0"/>
    <mass value="2.8540060742338134"/>
    <inertia ixx="0.0049" iyy="0.009384" izz="0.0049" ixy="0.0" iyz="0.0" ixz="-0.0"/>
  </inertial>
  <visual>
    <origin xyz="-0.26 0.31702 -0.06745" rpy="0 0 0"/>
    <geometry>
      <mesh filename="package://robot_rover1_description/meshes/right_1.stl" scale="0.001 0.001 0.001"/>
    </geometry>
    <material name="silver"/>
  </visual>
  <collision>
    <origin xyz="-0.26 0.31702 -0.06745" rpy="0 0 0"/>
    <geometry>
      <mesh filename="package://robot_rover1_description/meshes/right_1.stl" scale="0.001 0.001 0.001"/>
    </geometry>
  </collision>
</link>

<link name="left_1">
  <inertial>
    <origin xyz="2.1094237467877974e-15 0.014000000000001234 2.220446049250313e-15" rpy="0 0 0"/>
    <mass value="2.8540060742338134"/>
    <inertia ixx="0.0049" iyy="0.009384" izz="0.0049" ixy="0.0" iyz="0.0" ixz="0.0"/>
  </inertial>
  <visual>
    <origin xyz="-0.26 -0.31498 -0.06745" rpy="0 0 0"/>
    <geometry>
      <mesh filename="package://robot_rover1_description/meshes/left_1.stl" scale="0.001 0.001 0.001"/>
    </geometry>
    <material name="silver"/>
  </visual>
  <collision>
    <origin xyz="-0.26 -0.31498 -0.06745" rpy="0 0 0"/>
    <geometry>
      <mesh filename="package://robot_rover1_description/meshes/left_1.stl" scale="0.001 0.001 0.001"/>
    </geometry>
  </collision>
</link>

<link name="lidar_1">
  <inertial>
    <origin xyz="-7.7021722333370235e-16 -6.513886652292911e-16 0.0097386583312018" rpy="0 0 0"/>
    <mass value="0.8633166205873595"/>
    <inertia ixx="0.000407" iyy="0.000407" izz="0.000759" ixy="0.0" iyz="-0.0" ixz="-0.0"/>
  </inertial>
  <visual>
    <origin xyz="0.04275 0.00127 -0.591" rpy="0 0 0"/>
    <geometry>
      <mesh filename="package://robot_rover1_description/meshes/lidar_1.stl" scale="0.001 0.001 0.001"/>
    </geometry>
    <material name="silver"/>
  </visual>
  <collision>
    <origin xyz="0.04275 0.00127 -0.591" rpy="0 0 0"/>
    <geometry>
      <mesh filename="package://robot_rover1_description/meshes/lidar_1.stl" scale="0.001 0.001 0.001"/>
    </geometry>
  </collision>
</link>

<joint name="Revolute 6" type="continuous">
  <origin xyz="0.26 -0.31702 0.06745" rpy="0 0 0"/>
  <parent link="base_link"/>
  <child link="right_1"/>
  <axis xyz="0.0 1.0 0.0"/>
</joint>

<joint name="Revolute 7" type="continuous">
  <origin xyz="0.26 0.31498 0.06745" rpy="0 0 0"/>
  <parent link="base_link"/>
  <child link="left_1"/>
  <axis xyz="0.0 -1.0 -0.0"/>
</joint>

<joint name="Rigid 8" type="fixed">
  <origin xyz="-0.04275 -0.00127 0.591" rpy="0 0 0"/>
  <parent link="base_link"/>
  <child link="lidar_1"/>
</joint>

</robot>
